Workbook

Sheet 00_Metadata
A1: Field | B1: Value | C1: Source_URL | D1: Notes
A2: Model_ID | B2: VCF-AFA-CN | D2: Stable canonical model identifier
A3: Model_Name | B3: VCF-AFA Canonical Model | D3: Customer-facing VCF product/feature model with Functionality_ID as analysis key
A4: Model_Version | B4: v0.3 | D4: New top-level product list and rebuilt cascade
A5: Schema_Version | B5: 1.1 | D5: Adds Integration/Add-On registry and VCF 9.1 modeling columns
A6: Status | B6: Draft | D6: For review and further validation
A7: Target_Product_Count | B7: 12 | D7: Planning target
A8: Target_Feature_Count | B8: 80 | D8: Planning target
A9: Target_Functionality_Count | B9: 240 | D9: Planning target
A10: Official_Basis | B10: VCF 9.1 official Broadcom/VMware documentation and KBs | C10: https://techdocs.broadcom.com/us/en/vmware-cis/vcf/vcf-9-0-and-later/9-1/release-notes/vmware-cloud-foundation-9-1-0-0-release-notes.html | D10: Release notes and component BOM were used as primary scope anchors
A11: Primary_Scope_Decision | B11: 12 top-level products + integration/add-on registry | C11: https://techdocs.broadcom.com/us/en/vmware-cis/vcf/vcf-9-0-and-later/9-1/release-notes/vmware-cloud-foundation-9-1-0-0-release-notes/vmware-cloud-foundation-bill-of-materials.html | D11: Prevents endless top-level product churn
A12: Assessment_View | B12: VCF Product/Component -> Major Feature | D12: Workshop-facing capture model
A13: Scoring_Key | B13: Functionality_ID | D13: Analysis/scoring/parity key
A14: Created_Date | B14: 46196 | D14: Creation date
A15: Last_Updated | B15: 46196 | D15: Last update date
A16: Owner | B16: VCF-AFA | D16: Project owner placeholder
A17: Notes | B17: CN v0.3 is a rebuilt draft for review; not yet approved as final canonical scope.

Sheet 01_Products
A1: Product_ID | B1: Product_Name | C1: Product_Type | D1: Product_Description | E1: Assessment_Included | F1: Official_VCF91_Category | G1: Modeling_Treatment | H1: Entitlement_Treatment | I1: Primary_Source_URL | J1: Source_Confidence | K1: Sort_Order | L1: Status | M1: Notes
A2: PC-PLATFORM | B2: VCF Platform, Fleet & Workload Domains | C2: Platform | D2: Defines the VCF private cloud construct, fleet context, management and workload domain model, and deployment profile applicability. | E2: Yes | F2: VCF 9.1 Core | G2: Top-Level Product | H2: Core VCF | I2: https://techdocs.broadcom.com/us/en/vmware-cis/vcf/vcf-9-0-and-later/9-1/release-notes/vmware-cloud-foundation-9-1-0-0-release-notes/what-s-new.html | J2: High | K2: 1 | L2: Draft | M2: Rebased from CN v0.2 to stabilize VCF 9.1 customer-assessment surface.
A3: PC-LIFECYCLE | B3: VCF Installer, SDDC Manager & Lifecycle Services | C3: Lifecycle | D3: Covers Day 0 deployment, SDDC Manager orchestration, convergence/import, component lifecycle, software depot, and management-services lifecycle functions. | E3: Yes | F3: VCF 9.1 Core | G3: Top-Level Product | H3: Core VCF | I3: https://techdocs.broadcom.com/us/en/vmware-cis/vcf/vcf-9-0-and-later/9-1/release-notes/vmware-cloud-foundation-9-1-0-0-release-notes/vmware-cloud-foundation-bill-of-materials.html | J3: High | K3: 2 | L3: Draft | M3: Cloud Builder is represented here as a deployment/bring-up capability rather than as a top-level product.
A4: PC-VSPHERE | B4: vSphere Compute & Management | C4: Compute | D4: Combines vCenter and ESX/ESXi compute-management capabilities into one customer-facing product/component group. | E4: Yes | F4: VCF 9.1 Core | G4: Top-Level Product | H4: Core VCF | I4: https://techdocs.broadcom.com/us/en/vmware-cis/vcf/vcf-9-0-and-later/9-1/release-notes/vmware-cloud-foundation-9-1-0-0-release-notes/vmware-cloud-foundation-bill-of-materials.html | J4: High | K4: 3 | L4: Draft | M4: vCenter and ESX are kept as feature groups under one product to reduce model churn.
A5: PC-VSAN | B5: vSAN & Storage Services | C5: Storage | D5: Covers vSAN architecture, storage policies, resilience, file services, snapshots, external storage context, and storage data services. | E5: Yes | F5: VCF 9.1 Core | G5: Top-Level Product | H5: Core VCF | I5: https://techdocs.broadcom.com/us/en/vmware-cis/vcf/vcf-9-0-and-later/9-1/release-notes/vmware-cloud-foundation-9-1-0-0-release-notes/vmware-cloud-foundation-bill-of-materials.html | J5: High | K5: 4 | L5: Draft | M5: Includes vSAN ESA/OSA witness and file-services context from the BOM.
A6: PC-NSX-NET | B6: NSX Networking, Edge & VPC Services | C6: Network | D6: Covers NSX network virtualization, transport, edge, routing, IP services, VPN, VPC constructs, and load-balancer integration context. | E6: Yes | F6: VCF 9.1 Core | G6: Top-Level Product | H6: Core VCF | I6: https://techdocs.broadcom.com/us/en/vmware-cis/vcf/vcf-9-0-and-later/9-1/release-notes/vmware-cloud-foundation-9-1-0-0-release-notes/vmware-cloud-foundation-bill-of-materials.html | J6: High | K6: 5 | L6: Draft | M6: Avi is tracked as an integration/add-on; NSX Load Balancer transition context remains relevant.
A7: PC-NSX-SEC | B7: NSX Security & Firewall Services | C7: Security | D7: Covers NSX distributed security, gateway security, policy grouping, advanced threat services, security logging, and vDefend linkage. | E7: Yes | F7: VCF 9.1 Core / Advanced | G7: Top-Level Product | H7: Core plus add-on linkage | I7: https://www.vmware.com/docs/vmware-cloud-foundation-9-1-feature-comparison-and-upgrade-paths | J7: Medium | K7: 6 | L7: Draft | M7: Advanced Security/vDefend is kept in integration registry where separately licensed.
A8: PC-OPS | B8: VCF Operations & Observability | C8: Operations | D8: Covers VCF Operations, cloud proxy, network/log observability, real-time metrics, compliance posture, management packs, and business/capacity visibility. | E8: Yes | F8: VCF 9.1 Core | G8: Top-Level Product | H8: Core VCF with advanced-service linkage | I8: https://techdocs.broadcom.com/us/en/vmware-cis/vcf/vcf-9-0-and-later/9-1/release-notes/vmware-cloud-foundation-9-1-0-0-release-notes/what-s-new/whats-new-vcf-ops.html | J8: High | K8: 7 | L8: Draft | M8: VCF Operations for Networks and Logs are features/capabilities here, not separate products.
A9: PC-AUTOMATION | B9: VCF Automation & Self-Service | C9: Automation | D9: Covers self-service private cloud consumption, organizations/projects, catalogs, policy, provisioning, and extensibility. | E9: Yes | F9: VCF 9.1 Core | G9: Top-Level Product | H9: Core VCF | I9: https://techdocs.broadcom.com/us/en/vmware-cis/vcf/vcf-9-0-and-later/9-0/overview-of-vmware-cloud-foundation-9/what-is-vmware-cloud-foundation-and-vmware-vsphere-foundation/vcf-automation-overview.html | J9: High | K9: 8 | L9: Draft | M9: Former Aria Automation capabilities are modeled here under VCF Automation.
A10: PC-VKS | B10: vSphere Kubernetes Service & Application Platform | C10: Application Platform | D10: Covers Supervisor, VKS clusters, VM Service, supervisor services, registry, packages, ingress, and app platform services. | E10: Yes | F10: VCF 9.1 Core | G10: Top-Level Product | H10: Core VCF | I10: https://techdocs.broadcom.com/us/en/vmware-cis/vcf/vcf-9-0-and-later/9-1/release-notes/vmware-cloud-foundation-9-1-0-0-release-notes/vmware-cloud-foundation-bill-of-materials.html | J10: High | K10: 9 | L10: Draft | M10: Uses VKS terminology instead of broader legacy Tanzu naming.
A11: PC-MOBILITY | B11: HCX, Import, Converge & Workload Mobility | C11: Migration | D11: Covers HCX lifecycle, workload migration, network extension, import/converge workflows, and migration governance. | E11: Yes | F11: VCF 9.1 Core / Operations | G11: Top-Level Product | H11: Core VCF | I11: https://techdocs.broadcom.com/us/en/vmware-cis/vcf/vcf-9-0-and-later/9-1/release-notes/vmware-cloud-foundation-9-1-0-0-release-notes/vmware-cloud-foundation-bill-of-materials.html | J11: High | K11: 10 | L11: Draft | M11: HCX is explicit in VCF BOM and material to migration feasibility.
A12: PC-RESILIENCE | B12: Protection, Recovery & Resilience | C12: Resilience | D12: Covers VCF management backup/restore, replication, site recovery, vSAN snapshots, protection/recovery add-ons, and recovery validation. | E12: Yes | F12: VCF 9.1 Add-on / Core linkage | G12: Top-Level Product | H12: Core plus add-on linkage | I12: https://www.vmware.com/docs/vmware-cloud-foundation-9-1-feature-comparison-and-upgrade-paths | J12: Medium | K12: 11 | L12: Draft | M12: Separates resilience as an assessment axis because it strongly affects migration risk.
A13: PC-PRIVATEAI | B13: VCF Private AI Services | C13: AI | D13: Covers Private AI services, GPU/vGPU visibility, model runtime/store, AI blueprints, RAG/data indexing, and vector services. | E13: Yes | F13: VCF 9.1 Core / Advanced | G13: Top-Level Product | H13: Core VCF capability with advanced-service linkage | I13: https://www.vmware.com/docs/vmware-cloud-foundation-9-1-general-faqs | J13: Medium | K13: 12 | L13: Draft | M13: Included because VCF 9.1 positioning and APIs explicitly include Private AI services.

Sheet 01b_Integrations_AddOns
A1: Integration_ID | B1: Integration_Name | C1: Integration_Type | D1: Official_Status | E1: Core_or_AddOn | F1: Parent_Product_IDs | G1: Assessment_Relevance | H1: Include_By_Default | I1: Evidence_Source | J1: Evidence_Confidence | K1: Notes
A2: INT-AVI | B2: VMware Avi Load Balancer / NSX Advanced Load Balancer | C2: Advanced Service / Add-on | D2: Interoperable VCF add-on | E2: Add-on | F2: PC-NSX-NET;PC-VKS;PC-AUTOMATION | G2: High | H2: Conditional | I2: https://techdocs.broadcom.com/us/en/vmware-security-load-balancing/avi-load-balancer/avi-load-balancer-vmware-cloud-foundation/9-1.html | J2: High | K2: Mandatory registry item for load balancing; not promoted to top-level product to avoid model churn.
A3: INT-NSX-LB-TRANS | B3: NSX Load Balancer transition to Avi | C3: Transition / Compatibility | D3: VCF 9.0/9.1 transition article | E3: Transition | F3: PC-NSX-NET | G3: High | H3: Conditional | I3: https://knowledge.broadcom.com/external/article/439411/nsx-load-balancer-to-vmware-avi-load-bal.html | J3: High | K3: Track legacy NSX LB impact separately from core NSX networking.
A4: INT-DSM | B4: VMware Data Services Manager | C4: Advanced Service / Add-on | D4: VCF add-on | E4: Add-on | F4: PC-VKS;PC-AUTOMATION;PC-VSAN | G4: Medium | H4: Conditional | I4: https://techdocs.broadcom.com/us/en/vmware-cis/vcf/vcf-9-0-and-later/9-1/release-notes/vmware-cloud-foundation-9-1-0-0-release-notes/vmware-cloud-foundation-bill-of-materials.html | J4: High | K4: Data services should not force a separate top-level product unless assessment scope requires it.
A5: INT-PROTECTION-RECOVERY | B5: Protection and Recovery Add-on | C5: Advanced Service / Add-on | D5: VCF add-on | E5: Add-on | F5: PC-RESILIENCE | G5: High | H5: Conditional | I5: https://techdocs.broadcom.com/us/en/vmware-cis/vcf/vcf-9-0-and-later/9-1/release-notes/vmware-cloud-foundation-9-1-0-0-release-notes/vmware-cloud-foundation-bill-of-materials.html | J5: High | K5: Maps to Protection, Recovery & Resilience product.
A6: INT-DEEP-LEARNING-VM | B6: Deep Learning VM | C6: Advanced Service / AI | D6: VCF add-on | E6: Add-on | F6: PC-PRIVATEAI;PC-VSPHERE | G6: Medium | H6: Conditional | I6: https://techdocs.broadcom.com/us/en/vmware-cis/vcf/vcf-9-0-and-later/9-1/release-notes/vmware-cloud-foundation-9-1-0-0-release-notes/vmware-cloud-foundation-bill-of-materials.html | J6: High | K6: Tracked under Private AI / compute integration.
A7: INT-OPS-NETWORKS | B7: VCF Operations for Networks | C7: Operations Component | D7: VCF BOM component | E7: Core/Component | F7: PC-OPS;PC-NSX-NET | G7: High | H7: Yes | I7: https://techdocs.broadcom.com/us/en/vmware-cis/vcf/vcf-9-0-and-later/9-1/release-notes/vmware-cloud-foundation-9-1-0-0-release-notes/vmware-cloud-foundation-bill-of-materials.html | J7: High | K7: Feature group under VCF Operations & Observability, not a product.
A8: INT-OPS-LOGS | B8: Log Management / VCF Operations for Logs | C8: Operations Component | D8: VCF BOM component | E8: Core/Component | F8: PC-OPS | G8: High | H8: Yes | I8: https://techdocs.broadcom.com/us/en/vmware-cis/vcf/vcf-9-0-and-later/9-1/release-notes/vmware-cloud-foundation-9-1-0-0-release-notes/vmware-cloud-foundation-bill-of-materials.html | J8: High | K8: Feature group under VCF Operations & Observability.
A9: INT-CLOUD-PROXY | B9: Cloud Proxy | C9: Operations Component | D9: VCF BOM component | E9: Core/Component | F9: PC-OPS | G9: Medium | H9: Yes | I9: https://techdocs.broadcom.com/us/en/vmware-cis/vcf/vcf-9-0-and-later/9-1/release-notes/vmware-cloud-foundation-9-1-0-0-release-notes/vmware-cloud-foundation-bill-of-materials.html | J9: High | K9: Operations component, not assessment product.
A10: INT-LICENSE-SERVER | B10: VCF License Server | C10: Management Component | D10: VCF BOM component | E10: Core/Component | F10: PC-PLATFORM;PC-LIFECYCLE | G10: High | H10: Yes | I10: https://www.vmware.com/docs/vmware-cloud-foundation-9-1-general-faqs | J10: High | K10: Licensing component; captured in platform/lifecycle features.
A11: INT-FLEET-LCM | B11: Fleet Lifecycle | C11: Lifecycle Component | D11: Required component binary | E11: Core/Component | F11: PC-LIFECYCLE;PC-PLATFORM | G11: High | H11: Yes | I11: https://knowledge.broadcom.com/external/article/425089/required-component-binaries-for-vcf-91.html | J11: High | K11: Lifecycle internal component; not product.
A12: INT-SDDC-LCM | B12: SDDC Lifecycle | C12: Lifecycle Component | D12: Required component binary | E12: Core/Component | F12: PC-LIFECYCLE | G12: High | H12: Yes | I12: https://knowledge.broadcom.com/external/article/425089/required-component-binaries-for-vcf-91.html | J12: High | K12: Lifecycle internal component; not product.
... A27: INT-ECOSYSTEM | B27: ServiceNow / Ansible / Puppet / Salt / Infoblox / AD / IPAM integrations | C27: Ecosystem Integration | D27: External integration | E27: External | F27: PC-AUTOMATION;PC-OPS;PC-NSX-NET | G27: Medium | H27: Conditional | I27: https://www.vmware.com/docs/vmware-cloud-foundation-9-1-feature-comparison-and-upgrade-paths | J27: Medium | K27: External integrations should not create product rows.

Sheet 02_Features
B1: Product_ID | C1: Feature_Name | D1: Feature_Description | E1: Customer_Assessment_Prompt | F1: Default_Assessment_Level | G1: Requires_Functionality_Detail | H1: Default_Criticality | I1: Sovereignty_Relevance | J1: Primary_Analysis_Domain | K1: Capability_Group | L1: Sort_Order | M1: Status | N1: Primary_Source_URL | O1: Source_Confidence | P1: Notes
A2: FT-PLATFORM-01 | B2: PC-PLATFORM | C2: Platform architecture and taxonomy | D2: VCF instance, fleet, and private-cloud boundary model. | E2: Does the customer depend on VCF-wide platform/fleet constructs and workload-domain taxonomy? | F2: Feature | G2: No | H2: High | I2: Medium | J2: Management | K2: Platform Governance | L2: 1 | M2: Draft | N2: https://techdocs.broadcom.com/us/en/vmware-cis/vcf/vcf-9-0-and-later/9-1/release-notes/vmware-cloud-foundation-9-1-0-0-release-notes/what-s-new.html | O2: High | P2: CN v0.3 rebuilt cascade
A3: FT-PLATFORM-02 | B3: PC-PLATFORM | C3: Management domain and workload domain model | D3: Management domain and workload domain separation and composition. | E3: How important are VCF management/workload domain boundaries? | F3: Feature | G3: Yes | H3: Critical | I3: High | J3: Management | K3: Domain Architecture | L3: 2 | M3: Draft | N3: https://techdocs.broadcom.com/us/en/vmware-cis/vcf/vcf-9-0-and-later/9-1/release-notes/vmware-cloud-foundation-9-1-0-0-release-notes/vmware-cloud-foundation-bill-of-materials.html | O3: High | P3: CN v0.3 rebuilt cascade
A4: FT-PLATFORM-03 | B4: PC-PLATFORM | C4: Fleet management and multi-instance governance | D4: Multi-instance VCF visibility and fleet-governance context. | E4: Does the customer manage multiple VCF instances or require fleet-level governance? | F4: Feature | G4: Yes | H4: High | I4: Medium | J4: Management | K4: Fleet Management | L4: 3 | M4: Draft | N4: https://techdocs.broadcom.com/us/en/vmware-cis/vcf/vcf-9-0-and-later/9-1/release-notes/vmware-cloud-foundation-9-1-0-0-release-notes/what-s-new/whats-new-vcf-ops.html | O4: High | P4: CN v0.3 rebuilt cascade
A5: FT-PLATFORM-04 | B5: PC-PLATFORM | C5: VCF management services deployment model | D5: Common runtime and management-services component model. | E5: Does the customer require explicit control over VCF management services placement and availability? | F5: Feature | G5: Yes | H5: High | I5: Medium | J5: Operations | K5: Management Services | L5: 4 | M5: Draft | N5: https://techdocs.broadcom.com/us/en/vmware-cis/vcf/vcf-9-0-and-later/9-1/design/vmware-cloud-foundation-concepts/vcf-management-services-models.html | O5: High | P5: CN v0.3 rebuilt cascade
A6: FT-PLATFORM-05 | B6: PC-PLATFORM | C6: Identity, licensing and platform access context | D6: Platform identity, license server, and role context for VCF management. | E6: Are identity, licensing, and access-control mechanics material to the assessment? | F6: Feature | G6: Yes | H6: High | I6: High | J6: Security | K6: Access Governance | L6: 5 | M6: Draft | N6: https://www.vmware.com/docs/vmware-cloud-foundation-9-1-general-faqs | O6: High | P6: CN v0.3 rebuilt cascade
A7: FT-PLATFORM-06 | B7: PC-PLATFORM | C7: Deployment profile and edge applicability | D7: Standard, consolidated, edge, and site-topology applicability. | E7: Does the target environment include edge or constrained deployment profiles? | F7: Feature | G7: No | H7: Medium | I7: High | J7: Sovereignty | K7: Deployment Profile | L7: 6 | M7: Draft | N7: https://www.vmware.com/docs/vmware-cloud-foundation-9-1-general-faqs | O7: High | P7: CN v0.3 rebuilt cascade
A8: FT-LIFECYCLE-01 | B8: PC-LIFECYCLE | C8: VCF deployment and bring-up | D8: Installer-driven private-cloud deployment and bring-up workflows. | E8: Does the customer require VCF-style guided deployment and bring-up automation? | F8: Feature | G8: Yes | H8: Critical | I8: Medium | J8: Lifecycle | K8: Deployment Automation | L8: 1 | M8: Draft | N8: https://techdocs.broadcom.com/us/en/vmware-cis/vcf/vcf-9-0-and-later/9-1/release-notes/vmware-cloud-foundation-9-1-0-0-release-notes/vmware-cloud-foundation-bill-of-materials.html | O8: High | P8: CN v0.3 rebuilt cascade
A9: FT-LIFECYCLE-02 | B9: PC-LIFECYCLE | C9: SDDC Manager inventory and domain orchestration | D9: Domain inventory, domain creation, and orchestration functions. | E9: How important is SDDC Manager-style inventory and domain orchestration? | F9: Feature | G9: Yes | H9: Critical | I9: Medium | J9: Lifecycle | K9: Domain Orchestration | L9: 2 | M9: Draft | N9: https://techdocs.broadcom.com/us/en/vmware-cis/vcf/vcf-9-0-and-later/9-1/release-notes/vmware-cloud-foundation-9-1-0-0-release-notes/vmware-cloud-foundation-bill-of-materials.html | O9: High | P9: CN v0.3 rebuilt cascade
A10: FT-LIFECYCLE-03 | B10: PC-LIFECYCLE | C10: Converge and import workflows | D10: Brownfield import, converge, and environment onboarding workflows. | E10: Does the customer need import/converge paths from existing vSphere or VCF estates? | F10: Feature | G10: Yes | H10: High | I10: Medium | J10: Migration | K10: Import and Converge | L10: 3 | M10: Draft | N10: https://knowledge.broadcom.com/external/article/440630/upgrade-sequence-and-related-issues-for.html | O10: High | P10: CN v0.3 rebuilt cascade
A11: FT-LIFECYCLE-04 | B11: PC-LIFECYCLE | C11: Fleet and SDDC lifecycle management | D11: Fleet lifecycle and SDDC lifecycle services. | E11: Is automated multi-component lifecycle management a required operating model capability? | F11: Feature | G11: Yes | H11: Critical | I11: High | J11: Lifecycle | K11: Lifecycle Orchestration | L11: 4 | M11: Draft | N11: https://knowledge.broadcom.com/external/article/425089/required-component-binaries-for-vcf-91.html | O11: High | P11: CN v0.3 rebuilt cascade
A12: FT-LIFECYCLE-05 | B12: PC-LIFECYCLE | C12: Software depot and download tooling | D12: Software depot, download tooling, bundles, and metadata management. | E12: Does the customer require controlled software depot and download workflows? | F12: Feature | G12: No | H12: High | I12: High | J12: Lifecycle | K12: Software Supply | L12: 5 | M12: Draft | N12: https://knowledge.broadcom.com/external/article/425089/required-component-binaries-for-vcf-91.html | O12: High | P12: CN v0.3 rebuilt cascade
A13: FT-LIFECYCLE-06 | B13: PC-LIFECYCLE | C13: Lifecycle prechecks and remediation workflows | D13: Precheck, validation, remediation, and failed-upgrade control. | E13: How important are built-in upgrade prechecks and remediation workflows? | F13: Feature | G13: Yes | H13: Critical | I13: Medium | J13: Lifecycle | K13: Risk Control | L13: 6 | M13: Draft | N13: https://knowledge.broadcom.com/external/article/440630/upgrade-sequence-and-related-issues-for.html | O13: High | P13: CN v0.3 rebuilt cascade
... A81: FT-PRIVATEAI-04 | B81: PC-PRIVATEAI | C81: RAG, data indexing and vector services | D81: Retrieval augmented generation support, data indexing and vector database service context. | E81: Does the customer require RAG/data indexing/vector service support? | F81: Functionality | G81: Yes | H81: Medium | I81: High | J81: AI | K81: RAG Data Services | L81: 4 | M81: Draft | N81: https://www.vmware.com/docs/vmware-cloud-foundation-9-1-feature-comparison-and-upgrade-paths | O81: High | P81: CN v0.3 rebuilt cascade

Sheet 03_Functionalities
A1: Functionality_ID | B1: Feature_ID | C1: Product_ID | D1: Functionality_Name | E1: Functionality_Description | F1: Includes | G1: Excludes | H1: Comparator_Evaluation_Question | I1: Primary_Analysis_Domain | J1: Capability_Group | K1: Default_Criticality | L1: Sovereignty_Relevance | M1: Evidence_Expectation | N1: AI_Seed_Search_Terms | O1: Assessment_Enabled | P1: Sort_Order | Q1: Status | R1: Primary_Source_URL | S1: Source_Confidence | T1: Notes
A2: FN-PLATFORM-01-01 | B2: FT-PLATFORM-01 | C2: PC-PLATFORM | D2: VCF instance and fleet boundary definition | E2: Major functionality for vcf instance and fleet boundary definition. | F2: Includes major assessment behavior for vcf instance and fleet boundary definition in the context of platform architecture and taxonomy. | G2: Excludes low-level configuration toggles, cosmetic UI behavior, and implementation-specific inventory minutiae unless they materially affect parity or risk. | H2: Can the comparator provide defensible parity for vcf instance and fleet boundary definition with supportable evidence and acceptable operational impact? | I2: Management | J2: Platform Governance | K2: High | L2: Medium | M2: Official vendor documentation, release notes, validated KB/article, product guide, or architecture reference with version applicability. | N2: VCF 9.1 Platform architecture and taxonomy VCF instance and fleet boundary definition comparator parity evidence | O2: Yes | P2: 1 | Q2: Draft | R2: https://techdocs.broadcom.com/us/en/vmware-cis/vcf/vcf-9-0-and-later/9-1/release-notes/vmware-cloud-foundation-9-1-0-0-release-notes/what-s-new.html | S2: High | T2: Seeded from VCF 9.1 top-level product/component scope.
A3: FN-PLATFORM-01-02 | B3: FT-PLATFORM-01 | C3: PC-PLATFORM | D3: Private-cloud taxonomy and component scope | E3: Major functionality for private-cloud taxonomy and component scope. | F3: Includes major assessment behavior for private-cloud taxonomy and component scope in the context of platform architecture and taxonomy. | G3: Excludes low-level configuration toggles, cosmetic UI behavior, and implementation-specific inventory minutiae unless they materially affect parity or risk. | H3: Can the comparator provide defensible parity for private-cloud taxonomy and component scope with supportable evidence and acceptable operational impact? | I3: Management | J3: Platform Governance | K3: High | L3: Medium | M3: Official vendor documentation, release notes, validated KB/article, product guide, or architecture reference with version applicability. | N3: VCF 9.1 Platform architecture and taxonomy Private-cloud taxonomy and component scope comparator parity evidence | O3: Yes | P3: 2 | Q3: Draft | R3: https://techdocs.broadcom.com/us/en/vmware-cis/vcf/vcf-9-0-and-later/9-1/release-notes/vmware-cloud-foundation-9-1-0-0-release-notes/what-s-new.html | S3: High | T3: Seeded from VCF 9.1 top-level product/component scope.
A4: FN-PLATFORM-01-03 | B4: FT-PLATFORM-01 | C4: PC-PLATFORM | D4: Platform role and responsibility mapping | E4: Major functionality for platform role and responsibility mapping. | F4: Includes major assessment behavior for platform role and responsibility mapping in the context of platform architecture and taxonomy. | G4: Excludes low-level configuration toggles, cosmetic UI behavior, and implementation-specific inventory minutiae unless they materially affect parity or risk. | H4: Can the comparator provide defensible parity for platform role and responsibility mapping with supportable evidence and acceptable operational impact? | I4: Management | J4: Platform Governance | K4: High | L4: Medium | M4: Official vendor documentation, release notes, validated KB/article, product guide, or architecture reference with version applicability. | N4: VCF 9.1 Platform architecture and taxonomy Platform role and responsibility mapping comparator parity evidence | O4: Yes | P4: 3 | Q4: Draft | R4: https://techdocs.broadcom.com/us/en/vmware-cis/vcf/vcf-9-0-and-later/9-1/release-notes/vmware-cloud-foundation-9-1-0-0-release-notes/what-s-new.html | S4: High | T4: Seeded from VCF 9.1 top-level product/component scope.
A5: FN-PLATFORM-02-01 | B5: FT-PLATFORM-02 | C5: PC-PLATFORM | D5: Management domain separation | E5: Major functionality for management domain separation. | F5: Includes major assessment behavior for management domain separation in the context of management domain and workload domain model. | G5: Excludes low-level configuration toggles, cosmetic UI behavior, and implementation-specific inventory minutiae unless they materially affect parity or risk. | H5: Can the comparator provide defensible parity for management domain separation with supportable evidence and acceptable operational impact? | I5: Management | J5: Domain Architecture | K5: Critical | L5: High | M5: Official vendor documentation, release notes, validated KB/article, product guide, or architecture reference with version applicability. | N5: VCF 9.1 Management domain and workload domain model Management domain separation comparator parity evidence | O5: Yes | P5: 1 | Q5: Draft | R5: https://techdocs.broadcom.com/us/en/vmware-cis/vcf/vcf-9-0-and-later/9-1/release-notes/vmware-cloud-foundation-9-1-0-0-release-notes/vmware-cloud-foundation-bill-of-materials.html | S5: High | T5: Seeded from VCF 9.1 top-level product/component scope.
A6: FN-PLATFORM-02-02 | B6: FT-PLATFORM-02 | C6: PC-PLATFORM | D6: Workload domain creation and control | E6: Major functionality for workload domain creation and control. | F6: Includes major assessment behavior for workload domain creation and control in the context of management domain and workload domain model. | G6: Excludes low-level configuration toggles, cosmetic UI behavior, and implementation-specific inventory minutiae unless they materially affect parity or risk. | H6: Can the comparator provide defensible parity for workload domain creation and control with supportable evidence and acceptable operational impact? | I6: Management | J6: Domain Architecture | K6: Critical | L6: High | M6: Official vendor documentation, release notes, validated KB/article, product guide, or architecture reference with version applicability. | N6: VCF 9.1 Management domain and workload domain model Workload domain creation and control comparator parity evidence | O6: Yes | P6: 2 | Q6: Draft | R6: https://techdocs.broadcom.com/us/en/vmware-cis/vcf/vcf-9-0-and-later/9-1/release-notes/vmware-cloud-foundation-9-1-0-0-release-notes/vmware-cloud-foundation-bill-of-materials.html | S6: High | T6: Seeded from VCF 9.1 top-level product/component scope.
A7: FN-PLATFORM-02-03 | B7: FT-PLATFORM-02 | C7: PC-PLATFORM | D7: Domain-specific cluster and component mapping | E7: Major functionality for domain-specific cluster and component mapping. | F7: Includes major assessment behavior for domain-specific cluster and component mapping in the context of management domain and workload domain model. | G7: Excludes low-level configuration toggles, cosmetic UI behavior, and implementation-specific inventory minutiae unless they materially affect parity or risk. | H7: Can the comparator provide defensible parity for domain-specific cluster and component mapping with supportable evidence and acceptable operational impact? | I7: Management | J7: Domain Architecture | K7: Critical | L7: High | M7: Official vendor documentation, release notes, validated KB/article, product guide, or architecture reference with version applicability. | N7: VCF 9.1 Management domain and workload domain model Domain-specific cluster and component mapping comparator parity evidence | O7: Yes | P7: 3 | Q7: Draft | R7: https://techdocs.broadcom.com/us/en/vmware-cis/vcf/vcf-9-0-and-later/9-1/release-notes/vmware-cloud-foundation-9-1-0-0-release-notes/vmware-cloud-foundation-bill-of-materials.html | S7: High | T7: Seeded from VCF 9.1 top-level product/component scope.
A8: FN-PLATFORM-03-01 | B8: FT-PLATFORM-03 | C8: PC-PLATFORM | D8: Fleet inventory visibility | E8: Major functionality for fleet inventory visibility. | F8: Includes major assessment behavior for fleet inventory visibility in the context of fleet management and multi-instance governance. | G8: Excludes low-level configuration toggles, cosmetic UI behavior, and implementation-specific inventory minutiae unless they materially affect parity or risk. | H8: Can the comparator provide defensible parity for fleet inventory visibility with supportable evidence and acceptable operational impact? | I8: Management | J8: Fleet Management | K8: High | L8: Medium | M8: Official vendor documentation, release notes, validated KB/article, product guide, or architecture reference with version applicability. | N8: VCF 9.1 Fleet management and multi-instance governance Fleet inventory visibility comparator parity evidence | O8: Yes | P8: 1 | Q8: Draft | R8: https://techdocs.broadcom.com/us/en/vmware-cis/vcf/vcf-9-0-and-later/9-1/release-notes/vmware-cloud-foundation-9-1-0-0-release-notes/what-s-new/whats-new-vcf-ops.html | S8: High | T8: Seeded from VCF 9.1 top-level product/component scope.
A9: FN-PLATFORM-03-02 | B9: FT-PLATFORM-03 | C9: PC-PLATFORM | D9: Multi-instance operational governance | E9: Major functionality for multi-instance operational governance. | F9: Includes major assessment behavior for multi-instance operational governance in the context of fleet management and multi-instance governance. | G9: Excludes low-level configuration toggles, cosmetic UI behavior, and implementation-specific inventory minutiae unless they materially affect parity or risk. | H9: Can the comparator provide defensible parity for multi-instance operational governance with supportable evidence and acceptable operational impact? | I9: Management | J9: Fleet Management | K9: High | L9: Medium | M9: Official vendor documentation, release notes, validated KB/article, product guide, or architecture reference with version applicability. | N9: VCF 9.1 Fleet management and multi-instance governance Multi-instance operational governance comparator parity evidence | O9: Yes | P9: 2 | Q9: Draft | R9: https://techdocs.broadcom.com/us/en/vmware-cis/vcf/vcf-9-0-and-later/9-1/release-notes/vmware-cloud-foundation-9-1-0-0-release-notes/what-s-new/whats-new-vcf-ops.html | S9: High | T9: Seeded from VCF 9.1 top-level product/component scope.
A10: FN-PLATFORM-03-03 | B10: FT-PLATFORM-03 | C10: PC-PLATFORM | D10: Fleet-level policy and version awareness | E10: Major functionality for fleet-level policy and version awareness. | F10: Includes major assessment behavior for fleet-level policy and version awareness in the context of fleet management and multi-instance governance. | G10: Excludes low-level configuration toggles, cosmetic UI behavior, and implementation-specific inventory minutiae unless they materially affect parity or risk. | H10: Can the comparator provide defensible parity for fleet-level policy and version awareness with supportable evidence and acceptable operational impact? | I10: Management | J10: Fleet Management | K10: High | L10: Medium | M10: Official vendor documentation, release notes, validated KB/article, product guide, or architecture reference with version applicability. | N10: VCF 9.1 Fleet management and multi-instance governance Fleet-level policy and version awareness comparator parity evidence | O10: Yes | P10: 3 | Q10: Draft | R10: https://techdocs.broadcom.com/us/en/vmware-cis/vcf/vcf-9-0-and-later/9-1/release-notes/vmware-cloud-foundation-9-1-0-0-release-notes/what-s-new/whats-new-vcf-ops.html | S10: High | T10: Seeded from VCF 9.1 top-level product/component scope.
A11: FN-PLATFORM-04-01 | B11: FT-PLATFORM-04 | C11: PC-PLATFORM | D11: Management services placement model | E11: Major functionality for management services placement model. | F11: Includes major assessment behavior for management services placement model in the context of vcf management services deployment model. | G11: Excludes low-level configuration toggles, cosmetic UI behavior, and implementation-specific inventory minutiae unless they materially affect parity or risk. | H11: Can the comparator provide defensible parity for management services placement model with supportable evidence and acceptable operational impact? | I11: Operations | J11: Management Services | K11: High | L11: Medium | M11: Official vendor documentation, release notes, validated KB/article, product guide, or architecture reference with version applicability. | N11: VCF 9.1 VCF management services deployment model Management services placement model comparator parity evidence | O11: Yes | P11: 1 | Q11: Draft | R11: https://techdocs.broadcom.com/us/en/vmware-cis/vcf/vcf-9-0-and-later/9-1/design/vmware-cloud-foundation-concepts/vcf-management-services-models.html | S11: High | T11: Seeded from VCF 9.1 top-level product/component scope.
A12: FN-PLATFORM-04-02 | B12: FT-PLATFORM-04 | C12: PC-PLATFORM | D12: Management services availability model | E12: Major functionality for management services availability model. | F12: Includes major assessment behavior for management services availability model in the context of vcf management services deployment model. | G12: Excludes low-level configuration toggles, cosmetic UI behavior, and implementation-specific inventory minutiae unless they materially affect parity or risk. | H12: Can the comparator provide defensible parity for management services availability model with supportable evidence and acceptable operational impact? | I12: Operations | J12: Management Services | K12: High | L12: Medium | M12: Official vendor documentation, release notes, validated KB/article, product guide, or architecture reference with version applicability. | N12: VCF 9.1 VCF management services deployment model Management services availability model comparator parity evidence | O12: Yes | P12: 2 | Q12: Draft | R12: https://techdocs.broadcom.com/us/en/vmware-cis/vcf/vcf-9-0-and-later/9-1/design/vmware-cloud-foundation-concepts/vcf-management-services-models.html | S12: High | T12: Seeded from VCF 9.1 top-level product/component scope.
A13: FN-PLATFORM-04-03 | B13: FT-PLATFORM-04 | C13: PC-PLATFORM | D13: Management services network requirements | E13: Major functionality for management services network requirements. | F13: Includes major assessment behavior for management services network requirements in the context of vcf management services deployment model. | G13: Excludes low-level configuration toggles, cosmetic UI behavior, and implementation-specific inventory minutiae unless they materially affect parity or risk. | H13: Can the comparator provide defensible parity for management services network requirements with supportable evidence and acceptable operational impact? | I13: Operations | J13: Management Services | K13: High | L13: Medium | M13: Official vendor documentation, release notes, validated KB/article, product guide, or architecture reference with version applicability. | N13: VCF 9.1 VCF management services deployment model Management services network requirements comparator parity evidence | O13: Yes | P13: 3 | Q13: Draft | R13: https://techdocs.broadcom.com/us/en/vmware-cis/vcf/vcf-9-0-and-later/9-1/design/vmware-cloud-foundation-concepts/vcf-management-services-models.html | S13: High | T13: Seeded from VCF 9.1 top-level product/component scope.
... A241: FN-PRIVATEAI-04-03 | B241: FT-PRIVATEAI-04 | C241: PC-PRIVATEAI | D241: RAG workflow enablement | E241: Major functionality for rag workflow enablement. | F241: Includes major assessment behavior for rag workflow enablement in the context of rag, data indexing and vector services. | G241: Excludes low-level configuration toggles, cosmetic UI behavior, and implementation-specific inventory minutiae unless they materially affect parity or risk. | H241: Can the comparator provide defensible parity for rag workflow enablement with supportable evidence and acceptable operational impact? | I241: AI | J241: RAG Data Services | K241: Medium | L241: High | M241: Official vendor documentation, release notes, validated KB/article, product guide, or architecture reference with version applicability. | N241: VCF 9.1 RAG, data indexing and vector services RAG workflow enablement comparator parity evidence | O241: Yes | P241: 3 | Q241: Draft | R241: https://www.vmware.com/docs/vmware-cloud-foundation-9-1-feature-comparison-and-upgrade-paths | S241: High | T241: Seeded from VCF 9.1 top-level product/component scope.

Sheet 04_Enums
A1: Enum_Group | B1: Enum_Value | C1: Display_Order | D1: Active | E1: Notes
A2: Status | B2: Draft | C2: 1 | D2: Yes
A3: Status | B3: Review | C3: 2 | D3: Yes
A4: Status | B4: Approved | C4: 3 | D4: Yes
A5: Status | B5: Deprecated | C5: 4 | D5: Yes
A6: YesNo | B6: Yes | C6: 1 | D6: Yes
A7: YesNo | B7: No | C7: 2 | D7: Yes
A8: Assessment_Level | B8: Feature | C8: 1 | D8: Yes
A9: Assessment_Level | B9: Functionality | C9: 2 | D9: Yes
A10: Criticality | B10: Low | C10: 1 | D10: Yes
A11: Criticality | B11: Medium | C11: 2 | D11: Yes
A12: Criticality | B12: High | C12: 3 | D12: Yes
A13: Criticality | B13: Critical | C13: 4 | D13: Yes
... A64: Impact_Level | B64: High | C64: 4 | D64: Yes

Sheet 05_Quality_Checks
A1: Check_ID | B1: Check_Name | C1: Target | D1: Formula_or_Value | E1: Result_Status | F1: Notes
A2: QC-001 | B2: Product count | C2: 12 | D2: =COUNTA('01_Products'!A2:A100) -> 12 | E2: =IF(D2=C2,"Pass","Review") -> Pass | F2: Target is exactly 12.
A3: QC-002 | B3: Feature count | C3: 80 | D3: =COUNTA('02_Features'!A2:A500) -> 80 | E3: =IF(D3=C3,"Pass","Review") -> Pass | F3: Target is exactly 80.
A4: QC-003 | B4: Functionality count | C4: 240 | D4: =COUNTA('03_Functionalities'!A2:A1000) -> 240 | E4: =IF(D4=C4,"Pass","Review") -> Pass | F4: Target is exactly 240.
A5: QC-004 | B5: Average features per product | C5: 5-10 | D5: =D3/D2 -> 6.6666667 | E5: =IF(AND(D5>=5,D5<=10),"Pass","Review") -> Pass | F5: Expected planning range.
A6: QC-005 | B6: Average functionalities per feature | C6: 1-5 | D6: =D4/D3 -> 3 | E6: =IF(AND(D6>=1,D6<=5),"Pass","Review") -> Pass | F6: Expected planning range.
A7: QC-006 | B7: Duplicate Product_ID | C7: 0 | D7: 0 | E7: Pass | F7: Computed by build script; must be zero.
A8: QC-007 | B8: Duplicate Feature_ID | C8: 0 | D8: 0 | E8: Pass | F8: Computed by build script; must be zero.
A9: QC-008 | B9: Duplicate Functionality_ID | C9: 0 | D9: 0 | E9: Pass | F9: Computed by build script; must be zero.
A10: QC-009 | B10: Orphan Feature Product_ID | C10: 0 | D10: 0 | E10: Pass | F10: Computed by build script; must be zero.
A11: QC-010 | B11: Orphan Functionality Feature_ID | C11: 0 | D11: 0 | E11: Pass | F11: Computed by build script; must be zero.
A12: QC-011 | B12: Orphan Functionality Product_ID | C12: 0 | D12: 0 | E12: Pass | F12: Computed by build script; must be zero.

Sheet 06_Change_Log
A1: Change_ID | B1: Date | C1: Model_Version | D1: Changed_By | E1: Change_Type | F1: Affected_ID | G1: Change_Summary | H1: Rationale | I1: Impact | J1: Approval_Status
A2: CHG-CN-003-001 | B2: 46196 | C2: v0.3 | D2: VCF-AFA | E2: Restructure | F2: 01_Products | G2: Rebuilt top-level product/component list for VCF 9.1 around 12 stable products. | H2: Reduce model churn and align with official VCF 9.1 component scope. | I2: Requires VCF KB and Comparator KB mapping review against new Product_ID/Feature_ID structure. | J2: Draft
A3: CHG-CN-003-002 | B3: 46196 | C3: v0.3 | D3: VCF-AFA | E3: Add | F3: 01b_Integrations_AddOns | G3: Added Integration/Add-On registry to capture official advanced services and internal components without inflating product count. | H3: Prevent optional or internal components from repeatedly changing top-level model structure. | I3: App/KB loader should treat this as reference and conditional assessment metadata. | J3: Draft
A4: CHG-CN-003-003 | B4: 46196 | C4: v0.3 | D4: VCF-AFA | E4: Rebuild | F4: 02_Features/03_Functionalities | G4: Rebuilt cascade to 80 major features and 240 major functionalities. | H4: Keep workshop usable while preserving analysis granularity. | I4: Requires review and refinement before approval. | J4: Draft

Sheet 07_Source_References
A1: Source_ID | B1: Source_Title | C1: Source_Type | D1: Source_URL | E1: Source_Date | F1: Relevance | G1: Confidence
A2: SRC-VCF91-RN | B2: VMware Cloud Foundation 9.1 Release Notes | C2: Release Notes | D2: https://techdocs.broadcom.com/us/en/vmware-cis/vcf/vcf-9-0-and-later/9-1/release-notes/vmware-cloud-foundation-9-1-0-0-release-notes.html | E2: 2026-06 | F2: Primary release context and BOM entry point | G2: High
A3: SRC-VCF91-WHATSNEW | B3: What's New in VCF 9.1 | C3: Release Notes | D3: https://techdocs.broadcom.com/us/en/vmware-cis/vcf/vcf-9-0-and-later/9-1/release-notes/vmware-cloud-foundation-9-1-0-0-release-notes/what-s-new.html | E3: 2026-05 | F3: Component-level change organization | G3: High
A4: SRC-VCF91-BOM | B4: VCF 9.1 Bill of Materials | C4: BOM | D4: https://techdocs.broadcom.com/us/en/vmware-cis/vcf/vcf-9-0-and-later/9-1/release-notes/vmware-cloud-foundation-9-1-0-0-release-notes/vmware-cloud-foundation-bill-of-materials.html | E4: 2026-05 | F4: Primary component/add-on basis | G4: High
A5: SRC-VCF91-FAQ | B5: VCF 9.1 General FAQ | C5: FAQ | D5: https://www.vmware.com/docs/vmware-cloud-foundation-9-1-general-faqs | E5: 2026-05 | F5: Licensing, components, advanced services context | G5: Medium
A6: SRC-VCF91-FEATURE-COMP | B6: VCF 9.1 Feature Comparison & Upgrade Paths | C6: Feature Comparison | D6: https://www.vmware.com/docs/vmware-cloud-foundation-9-1-feature-comparison-and-upgrade-paths | E6: 2026-05 | F6: Advanced services and capability comparison | G6: Medium
A7: SRC-VCF91-REQ-BIN | B7: Required Component Binaries for VCF 9.1 upgrade | C7: KB | D7: https://knowledge.broadcom.com/external/article/425089/required-component-binaries-for-vcf-91.html | E7: 2026-05 | F7: Management services component validation | G7: High
A8: SRC-VCF91-UPGRADE-SEQ | B8: Upgrade Sequence and Related Issues for VCF 9.1 | C8: KB | D8: https://knowledge.broadcom.com/external/article/440630/upgrade-sequence-and-related-issues-for.html | E8: 2026-06 | F8: Management services and upgrade-context validation | G8: High
A9: SRC-VCF91-OPS | B9: VCF Operations in VCF 9.1 | C9: Release Notes | D9: https://techdocs.broadcom.com/us/en/vmware-cis/vcf/vcf-9-0-and-later/9-1/release-notes/vmware-cloud-foundation-9-1-0-0-release-notes/what-s-new/whats-new-vcf-ops.html | E9: 2026-06 | F9: Operations and observability capabilities | G9: High
A10: SRC-VCF91-API | B10: VCF 9.1 API/SDK/CLI Changelog | C10: API Changelog | D10: https://techdocs.broadcom.com/us/en/vmware-cis/vcf/vcf-9-0-and-later/9-1/release-notes/vmware-cloud-foundation-9-1-0-0-release-notes/what-s-new/whats-new-vcf-cli-api-sdk/vcf-changelog.html | E10: 2026-05 | F10: API layer coverage across components | G10: Medium
A11: SRC-AVI-91 | B11: Avi Load Balancer for VCF 9.1 | C11: Product Docs | D11: https://techdocs.broadcom.com/us/en/vmware-security-load-balancing/avi-load-balancer/avi-load-balancer-vmware-cloud-foundation/9-1.html | E11: 2026-05 | F11: Avi integration/add-on scope | G11: High
A12: SRC-NSX-LB-AVI | B12: NSX Load Balancer to Avi Load Balancer Migration | C12: KB | D12: https://knowledge.broadcom.com/external/article/439411/nsx-load-balancer-to-vmware-avi-load-bal.html | E12: 2026-06 | F12: NSX load-balancer transition context | G12: High

Sheet 99_App_Load_View
A1: Functionality_ID | B1: Feature_ID | C1: Product_ID | D1: Product_Name | E1: Product_Type | F1: Feature_Name | G1: Customer_Assessment_Prompt | H1: Functionality_Name | I1: Functionality_Description | J1: Includes | K1: Excludes | L1: Primary_Analysis_Domain | M1: Capability_Group | N1: Default_Criticality | O1: Sovereignty_Relevance | P1: Evidence_Expectation | Q1: AI_Seed_Search_Terms | R1: Assessment_Enabled | S1: Product_Sort_Order | T1: Feature_Sort_Order | U1: Functionality_Sort_Order | V1: Status | W1: Primary_Source_URL | X1: Source_Confidence
A2: =IF('03_Functionalities'!A2="","",'03_Functionalities'!A2) -> FN-PLATFORM-01-01 | B2: =IF('03_Functionalities'!B2="","",'03_Functionalities'!B2) -> FT-PLATFORM-01 | C2: =IF('03_Functionalities'!C2="","",'03_Functionalities'!C2) -> PC-PLATFORM | D2: =IF(C2="","",_xludf.XLOOKUP(C2,'01_Products'!A:A,'01_Products'!B:B,"Missing Product")) -> #NAME? | E2: =IF(C2="","",_xludf.XLOOKUP(C2,'01_Products'!A:A,'01_Products'!C:C,"Missing Type")) -> #NAME? | F2: =IF(B2="","",_xludf.XLOOKUP(B2,'02_Features'!A:A,'02_Features'!C:C,"Missing Feature")) -> #NAME? | G2: =IF(B2="","",_xludf.XLOOKUP(B2,'02_Features'!A:A,'02_Features'!E:E,"Missing Prompt")) -> #NAME? | H2: =IF('03_Functionalities'!D2="","",'03_Functionalities'!D2) -> VCF instance and fleet boundary definition | I2: =IF('03_Functionalities'!E2="","",'03_Functionalities'!E2) -> Major functionality for vcf instance and fleet boundary definition. | J2: =IF('03_Functionalities'!F2="","",'03_Functionalities'!F2) -> Includes major assessment behavior for vcf instance and fleet boundary definition in the context of platform architecture and taxonomy. | K2: =IF('03_Functionalities'!G2="","",'03_Functionalities'!G2) -> Excludes low-level configuration toggles, cosmetic UI behavior, and implementation-specific inventory minutiae unless they materially affect parity or risk. | L2: =IF('03_Functionalities'!I2="","",'03_Functionalities'!I2) -> Management | M2: =IF('03_Functionalities'!J2="","",'03_Functionalities'!J2) -> Platform Governance | N2: =IF('03_Functionalities'!K2="","",'03_Functionalities'!K2) -> High | O2: =IF('03_Functionalities'!L2="","",'03_Functionalities'!L2) -> Medium | P2: =IF('03_Functionalities'!M2="","",'03_Functionalities'!M2) -> Official vendor documentation, release notes, validated KB/article, product guide, or architecture reference with version applicability. | Q2: =IF('03_Functionalities'!N2="","",'03_Functionalities'!N2) -> VCF 9.1 Platform architecture and taxonomy VCF instance and fleet boundary definition comparator parity evidence | R2: =IF('03_Functionalities'!O2="","",'03_Functionalities'!O2) -> Yes | S2: =IF(C2="","",_xludf.XLOOKUP(C2,'01_Products'!A:A,'01_Products'!K:K,0)) -> #NAME? | T2: =IF(B2="","",_xludf.XLOOKUP(B2,'02_Features'!A:A,'02_Features'!L:L,0)) -> #NAME? | U2: =IF('03_Functionalities'!P2="","",'03_Functionalities'!P2) -> 1 | V2: =IF('03_Functionalities'!Q2="","",'03_Functionalities'!Q2) -> Draft | W2: =IF('03_Functionalities'!R2="","",'03_Functionalities'!R2) -> https://techdocs.broadcom.com/us/en/vmware-cis/vcf/vcf-9-0-and-later/9-1/release-notes/vmware-cloud-foundation-9-1-0-0-release-notes/what-s-new.html | X2: =IF('03_Functionalities'!S2="","",'03_Functionalities'!S2) -> High
A3: =IF('03_Functionalities'!A3="","",'03_Functionalities'!A3) -> FN-PLATFORM-01-02 | B3: =IF('03_Functionalities'!B3="","",'03_Functionalities'!B3) -> FT-PLATFORM-01 | C3: =IF('03_Functionalities'!C3="","",'03_Functionalities'!C3) -> PC-PLATFORM | D3: =IF(C3="","",_xludf.XLOOKUP(C3,'01_Products'!A:A,'01_Products'!B:B,"Missing Product")) -> #NAME? | E3: =IF(C3="","",_xludf.XLOOKUP(C3,'01_Products'!A:A,'01_Products'!C:C,"Missing Type")) -> #NAME? | F3: =IF(B3="","",_xludf.XLOOKUP(B3,'02_Features'!A:A,'02_Features'!C:C,"Missing Feature")) -> #NAME? | G3: =IF(B3="","",_xludf.XLOOKUP(B3,'02_Features'!A:A,'02_Features'!E:E,"Missing Prompt")) -> #NAME? | H3: =IF('03_Functionalities'!D3="","",'03_Functionalities'!D3) -> Private-cloud taxonomy and component scope | I3: =IF('03_Functionalities'!E3="","",'03_Functionalities'!E3) -> Major functionality for private-cloud taxonomy and component scope. | J3: =IF('03_Functionalities'!F3="","",'03_Functionalities'!F3) -> Includes major assessment behavior for private-cloud taxonomy and component scope in the context of platform architecture and taxonomy. | K3: =IF('03_Functionalities'!G3="","",'03_Functionalities'!G3) -> Excludes low-level configuration toggles, cosmetic UI behavior, and implementation-specific inventory minutiae unless they materially affect parity or risk. | L3: =IF('03_Functionalities'!I3="","",'03_Functionalities'!I3) -> Management | M3: =IF('03_Functionalities'!J3="","",'03_Functionalities'!J3) -> Platform Governance | N3: =IF('03_Functionalities'!K3="","",'03_Functionalities'!K3) -> High | O3: =IF('03_Functionalities'!L3="","",'03_Functionalities'!L3) -> Medium | P3: =IF('03_Functionalities'!M3="","",'03_Functionalities'!M3) -> Official vendor documentation, release notes, validated KB/article, product guide, or architecture reference with version applicability. | Q3: =IF('03_Functionalities'!N3="","",'03_Functionalities'!N3) -> VCF 9.1 Platform architecture and taxonomy Private-cloud taxonomy and component scope comparator parity evidence | R3: =IF('03_Functionalities'!O3="","",'03_Functionalities'!O3) -> Yes | S3: =IF(C3="","",_xludf.XLOOKUP(C3,'01_Products'!A:A,'01_Products'!K:K,0)) -> #NAME? | T3: =IF(B3="","",_xludf.XLOOKUP(B3,'02_Features'!A:A,'02_Features'!L:L,0)) -> #NAME? | U3: =IF('03_Functionalities'!P3="","",'03_Functionalities'!P3) -> 2 | V3: =IF('03_Functionalities'!Q3="","",'03_Functionalities'!Q3) -> Draft | W3: =IF('03_Functionalities'!R3="","",'03_Functionalities'!R3) -> https://techdocs.broadcom.com/us/en/vmware-cis/vcf/vcf-9-0-and-later/9-1/release-notes/vmware-cloud-foundation-9-1-0-0-release-notes/what-s-new.html | X3: =IF('03_Functionalities'!S3="","",'03_Functionalities'!S3) -> High
A4: =IF('03_Functionalities'!A4="","",'03_Functionalities'!A4) -> FN-PLATFORM-01-03 | B4: =IF('03_Functionalities'!B4="","",'03_Functionalities'!B4) -> FT-PLATFORM-01 | C4: =IF('03_Functionalities'!C4="","",'03_Functionalities'!C4) -> PC-PLATFORM | D4: =IF(C4="","",_xludf.XLOOKUP(C4,'01_Products'!A:A,'01_Products'!B:B,"Missing Product")) -> #NAME? | E4: =IF(C4="","",_xludf.XLOOKUP(C4,'01_Products'!A:A,'01_Products'!C:C,"Missing Type")) -> #NAME? | F4: =IF(B4="","",_xludf.XLOOKUP(B4,'02_Features'!A:A,'02_Features'!C:C,"Missing Feature")) -> #NAME? | G4: =IF(B4="","",_xludf.XLOOKUP(B4,'02_Features'!A:A,'02_Features'!E:E,"Missing Prompt")) -> #NAME? | H4: =IF('03_Functionalities'!D4="","",'03_Functionalities'!D4) -> Platform role and responsibility mapping | I4: =IF('03_Functionalities'!E4="","",'03_Functionalities'!E4) -> Major functionality for platform role and responsibility mapping. | J4: =IF('03_Functionalities'!F4="","",'03_Functionalities'!F4) -> Includes major assessment behavior for platform role and responsibility mapping in the context of platform architecture and taxonomy. | K4: =IF('03_Functionalities'!G4="","",'03_Functionalities'!G4) -> Excludes low-level configuration toggles, cosmetic UI behavior, and implementation-specific inventory minutiae unless they materially affect parity or risk. | L4: =IF('03_Functionalities'!I4="","",'03_Functionalities'!I4) -> Management | M4: =IF('03_Functionalities'!J4="","",'03_Functionalities'!J4) -> Platform Governance | N4: =IF('03_Functionalities'!K4="","",'03_Functionalities'!K4) -> High | O4: =IF('03_Functionalities'!L4="","",'03_Functionalities'!L4) -> Medium | P4: =IF('03_Functionalities'!M4="","",'03_Functionalities'!M4) -> Official vendor documentation, release notes, validated KB/article, product guide, or architecture reference with version applicability. | Q4: =IF('03_Functionalities'!N4="","",'03_Functionalities'!N4) -> VCF 9.1 Platform architecture and taxonomy Platform role and responsibility mapping comparator parity evidence | R4: =IF('03_Functionalities'!O4="","",'03_Functionalities'!O4) -> Yes | S4: =IF(C4="","",_xludf.XLOOKUP(C4,'01_Products'!A:A,'01_Products'!K:K,0)) -> #NAME? | T4: =IF(B4="","",_xludf.XLOOKUP(B4,'02_Features'!A:A,'02_Features'!L:L,0)) -> #NAME? | U4: =IF('03_Functionalities'!P4="","",'03_Functionalities'!P4) -> 3 | V4: =IF('03_Functionalities'!Q4="","",'03_Functionalities'!Q4) -> Draft | W4: =IF('03_Functionalities'!R4="","",'03_Functionalities'!R4) -> https://techdocs.broadcom.com/us/en/vmware-cis/vcf/vcf-9-0-and-later/9-1/release-notes/vmware-cloud-foundation-9-1-0-0-release-notes/what-s-new.html | X4: =IF('03_Functionalities'!S4="","",'03_Functionalities'!S4) -> High
A5: =IF('03_Functionalities'!A5="","",'03_Functionalities'!A5) -> FN-PLATFORM-02-01 | B5: =IF('03_Functionalities'!B5="","",'03_Functionalities'!B5) -> FT-PLATFORM-02 | C5: =IF('03_Functionalities'!C5="","",'03_Functionalities'!C5) -> PC-PLATFORM | D5: =IF(C5="","",_xludf.XLOOKUP(C5,'01_Products'!A:A,'01_Products'!B:B,"Missing Product")) -> #NAME? | E5: =IF(C5="","",_xludf.XLOOKUP(C5,'01_Products'!A:A,'01_Products'!C:C,"Missing Type")) -> #NAME? | F5: =IF(B5="","",_xludf.XLOOKUP(B5,'02_Features'!A:A,'02_Features'!C:C,"Missing Feature")) -> #NAME? | G5: =IF(B5="","",_xludf.XLOOKUP(B5,'02_Features'!A:A,'02_Features'!E:E,"Missing Prompt")) -> #NAME? | H5: =IF('03_Functionalities'!D5="","",'03_Functionalities'!D5) -> Management domain separation | I5: =IF('03_Functionalities'!E5="","",'03_Functionalities'!E5) -> Major functionality for management domain separation. | J5: =IF('03_Functionalities'!F5="","",'03_Functionalities'!F5) -> Includes major assessment behavior for management domain separation in the context of management domain and workload domain model. | K5: =IF('03_Functionalities'!G5="","",'03_Functionalities'!G5) -> Excludes low-level configuration toggles, cosmetic UI behavior, and implementation-specific inventory minutiae unless they materially affect parity or risk. | L5: =IF('03_Functionalities'!I5="","",'03_Functionalities'!I5) -> Management | M5: =IF('03_Functionalities'!J5="","",'03_Functionalities'!J5) -> Domain Architecture | N5: =IF('03_Functionalities'!K5="","",'03_Functionalities'!K5) -> Critical | O5: =IF('03_Functionalities'!L5="","",'03_Functionalities'!L5) -> High | P5: =IF('03_Functionalities'!M5="","",'03_Functionalities'!M5) -> Official vendor documentation, release notes, validated KB/article, product guide, or architecture reference with version applicability. | Q5: =IF('03_Functionalities'!N5="","",'03_Functionalities'!N5) -> VCF 9.1 Management domain and workload domain model Management domain separation comparator parity evidence | R5: =IF('03_Functionalities'!O5="","",'03_Functionalities'!O5) -> Yes | S5: =IF(C5="","",_xludf.XLOOKUP(C5,'01_Products'!A:A,'01_Products'!K:K,0)) -> #NAME? | T5: =IF(B5="","",_xludf.XLOOKUP(B5,'02_Features'!A:A,'02_Features'!L:L,0)) -> #NAME? | U5: =IF('03_Functionalities'!P5="","",'03_Functionalities'!P5) -> 1 | V5: =IF('03_Functionalities'!Q5="","",'03_Functionalities'!Q5) -> Draft | W5: =IF('03_Functionalities'!R5="","",'03_Functionalities'!R5) -> https://techdocs.broadcom.com/us/en/vmware-cis/vcf/vcf-9-0-and-later/9-1/release-notes/vmware-cloud-foundation-9-1-0-0-release-notes/vmware-cloud-foundation-bill-of-materials.html | X5: =IF('03_Functionalities'!S5="","",'03_Functionalities'!S5) -> High
A6: =IF('03_Functionalities'!A6="","",'03_Functionalities'!A6) -> FN-PLATFORM-02-02 | B6: =IF('03_Functionalities'!B6="","",'03_Functionalities'!B6) -> FT-PLATFORM-02 | C6: =IF('03_Functionalities'!C6="","",'03_Functionalities'!C6) -> PC-PLATFORM | D6: =IF(C6="","",_xludf.XLOOKUP(C6,'01_Products'!A:A,'01_Products'!B:B,"Missing Product")) -> #NAME? | E6: =IF(C6="","",_xludf.XLOOKUP(C6,'01_Products'!A:A,'01_Products'!C:C,"Missing Type")) -> #NAME? | F6: =IF(B6="","",_xludf.XLOOKUP(B6,'02_Features'!A:A,'02_Features'!C:C,"Missing Feature")) -> #NAME? | G6: =IF(B6="","",_xludf.XLOOKUP(B6,'02_Features'!A:A,'02_Features'!E:E,"Missing Prompt")) -> #NAME? | H6: =IF('03_Functionalities'!D6="","",'03_Functionalities'!D6) -> Workload domain creation and control | I6: =IF('03_Functionalities'!E6="","",'03_Functionalities'!E6) -> Major functionality for workload domain creation and control. | J6: =IF('03_Functionalities'!F6="","",'03_Functionalities'!F6) -> Includes major assessment behavior for workload domain creation and control in the context of management domain and workload domain model. | K6: =IF('03_Functionalities'!G6="","",'03_Functionalities'!G6) -> Excludes low-level configuration toggles, cosmetic UI behavior, and implementation-specific inventory minutiae unless they materially affect parity or risk. | L6: =IF('03_Functionalities'!I6="","",'03_Functionalities'!I6) -> Management | M6: =IF('03_Functionalities'!J6="","",'03_Functionalities'!J6) -> Domain Architecture | N6: =IF('03_Functionalities'!K6="","",'03_Functionalities'!K6) -> Critical | O6: =IF('03_Functionalities'!L6="","",'03_Functionalities'!L6) -> High | P6: =IF('03_Functionalities'!M6="","",'03_Functionalities'!M6) -> Official vendor documentation, release notes, validated KB/article, product guide, or architecture reference with version applicability. | Q6: =IF('03_Functionalities'!N6="","",'03_Functionalities'!N6) -> VCF 9.1 Management domain and workload domain model Workload domain creation and control comparator parity evidence | R6: =IF('03_Functionalities'!O6="","",'03_Functionalities'!O6) -> Yes | S6: =IF(C6="","",_xludf.XLOOKUP(C6,'01_Products'!A:A,'01_Products'!K:K,0)) -> #NAME? | T6: =IF(B6="","",_xludf.XLOOKUP(B6,'02_Features'!A:A,'02_Features'!L:L,0)) -> #NAME? | U6: =IF('03_Functionalities'!P6="","",'03_Functionalities'!P6) -> 2 | V6: =IF('03_Functionalities'!Q6="","",'03_Functionalities'!Q6) -> Draft | W6: =IF('03_Functionalities'!R6="","",'03_Functionalities'!R6) -> https://techdocs.broadcom.com/us/en/vmware-cis/vcf/vcf-9-0-and-later/9-1/release-notes/vmware-cloud-foundation-9-1-0-0-release-notes/vmware-cloud-foundation-bill-of-materials.html | X6: =IF('03_Functionalities'!S6="","",'03_Functionalities'!S6) -> High
